Workbook

Sheet overview
A1: The analysis of the `delegated_tasks` data reveals insights into task performance across different categories.
A3: Here are the key takeaways: * **Overall Task Performance by Category:**
A4: * The `computer_programmers` category has the highest pass rate at approximately 94.12%, with 16 out of 17 tasks passed.
A5: * The `hr` category also shows a strong performance, with a pass rate of 90.00% (18 out of 20 tasks passed).
A6: * `marketing` and `operations` categories have moderate pass rates of 82.35% and 78.57% respectively.

Sheet delegated_tasks
B1: Task ID | C1: Member IDs | D1: Agent IDs | E1: Created At | F1: Updated At | G1: deepflow_task_id | H1: category | I1: Passed
A2: 0 | B2: 295 | C2: 30 | D2: 11 | E2: 2025-07-27T18:28:54.700Z | F2: 2025-07-27T18:28:54.700Z | G2: =VLOOKUP(B2,tasks!B2:C74,2,FALSE) -> computer_programmers_0 | H2: =LEFT(G2,FIND("_"&RIGHT(G2,LEN(G2)-FIND("@",SUBSTITUTE(G2,"_","@",LEN(G2)-LEN(SUBSTITUTE(G2,"_",""))))),G2)-1) -> computer_programmers | I2: TRUE
A3: 1 | B3: 296 | C3: 30 | D3: 11 | E3: 2025-07-27T18:29:00.737Z | F3: 2025-07-27T18:29:00.737Z | G3: =VLOOKUP(B3,tasks!B3:C75,2,FALSE) -> computer_programmers_1 | H3: =LEFT(G3,FIND("_"&RIGHT(G3,LEN(G3)-FIND("@",SUBSTITUTE(G3,"_","@",LEN(G3)-LEN(SUBSTITUTE(G3,"_",""))))),G3)-1) -> computer_programmers | I3: TRUE
A4: 2 | B4: 297 | C4: 30 | D4: 11 | E4: 2025-07-27T18:29:07.144Z | F4: 2025-07-27T18:29:07.144Z | G4: =VLOOKUP(B4,tasks!B4:C76,2,FALSE) -> computer_programmers_2 | H4: =LEFT(G4,FIND("_"&RIGHT(G4,LEN(G4)-FIND("@",SUBSTITUTE(G4,"_","@",LEN(G4)-LEN(SUBSTITUTE(G4,"_",""))))),G4)-1) -> computer_programmers | I4: TRUE
A5: 3 | B5: 298 | C5: 30 | D5: 11 | E5: 2025-07-27T18:29:18.458Z | F5: 2025-07-27T18:29:18.458Z | G5: =VLOOKUP(B5,tasks!B5:C77,2,FALSE) -> computer_programmers_3 | H5: =LEFT(G5,FIND("_"&RIGHT(G5,LEN(G5)-FIND("@",SUBSTITUTE(G5,"_","@",LEN(G5)-LEN(SUBSTITUTE(G5,"_",""))))),G5)-1) -> computer_programmers | I5: TRUE
A6: 4 | B6: 299 | C6: 30 | D6: 11 | E6: 2025-07-27T18:29:26.971Z | F6: 2025-07-27T18:29:26.971Z | G6: =VLOOKUP(B6,tasks!B6:C78,2,FALSE) -> computer_programmers_4 | H6: =LEFT(G6,FIND("_"&RIGHT(G6,LEN(G6)-FIND("@",SUBSTITUTE(G6,"_","@",LEN(G6)-LEN(SUBSTITUTE(G6,"_",""))))),G6)-1) -> computer_programmers | I6: TRUE
A7: 5 | B7: 300 | C7: 30,26 | D7: 11 | E7: 2025-07-27T18:29:34.938Z | F7: 2025-07-27T18:29:34.938Z | G7: =VLOOKUP(B7,tasks!B7:C79,2,FALSE) -> computer_programmers_5 | H7: =LEFT(G7,FIND("_"&RIGHT(G7,LEN(G7)-FIND("@",SUBSTITUTE(G7,"_","@",LEN(G7)-LEN(SUBSTITUTE(G7,"_",""))))),G7)-1) -> computer_programmers | I7: TRUE
A8: 6 | B8: 301 | C8: 30 | D8: 11 | E8: 2025-07-27T18:29:41.885Z | F8: 2025-07-27T18:29:41.885Z | G8: =VLOOKUP(B8,tasks!B8:C80,2,FALSE) -> computer_programmers_6 | H8: =LEFT(G8,FIND("_"&RIGHT(G8,LEN(G8)-FIND("@",SUBSTITUTE(G8,"_","@",LEN(G8)-LEN(SUBSTITUTE(G8,"_",""))))),G8)-1) -> computer_programmers | I8: TRUE
A9: 7 | B9: 302 | C9: 30 | D9: 11 | E9: 2025-07-27T18:29:49.900Z | F9: 2025-07-27T18:29:49.900Z | G9: =VLOOKUP(B9,tasks!B9:C81,2,FALSE) -> computer_programmers_7 | H9: =LEFT(G9,FIND("_"&RIGHT(G9,LEN(G9)-FIND("@",SUBSTITUTE(G9,"_","@",LEN(G9)-LEN(SUBSTITUTE(G9,"_",""))))),G9)-1) -> computer_programmers | I9: TRUE | J9: 30 | K9: 11
A10: 8 | B10: 303 | C10: 30 | D10: 11 | E10: 2025-07-27T18:29:56.575Z | F10: 2025-07-27T18:29:56.575Z | G10: =VLOOKUP(B10,tasks!B10:C82,2,FALSE) -> computer_programmers_8 | H10: =LEFT(G10,FIND("_"&RIGHT(G10,LEN(G10)-FIND("@",SUBSTITUTE(G10,"_","@",LEN(G10)-LEN(SUBSTITUTE(G10,"_",""))))),G10)-1) -> computer_programmers | I10: TRUE
A11: 9 | B11: 304 | C11: 30 | D11: 11 | E11: 2025-07-27T18:30:03.689Z | F11: 2025-07-27T18:30:03.689Z | G11: =VLOOKUP(B11,tasks!B11:C83,2,FALSE) -> computer_programmers_9 | H11: =LEFT(G11,FIND("_"&RIGHT(G11,LEN(G11)-FIND("@",SUBSTITUTE(G11,"_","@",LEN(G11)-LEN(SUBSTITUTE(G11,"_",""))))),G11)-1) -> computer_programmers | I11: TRUE
A12: 10 | B12: 305 | C12: 27 | D12: 9,8 | E12: 2025-07-27T18:30:20.976Z | F12: 2025-07-27T18:30:20.976Z | G12: =VLOOKUP(B12,tasks!B12:C84,2,FALSE) -> computer_programmers_10 | H12: =LEFT(G12,FIND("_"&RIGHT(G12,LEN(G12)-FIND("@",SUBSTITUTE(G12,"_","@",LEN(G12)-LEN(SUBSTITUTE(G12,"_",""))))),G12)-1) -> computer_programmers | I12: FALSE
A13: 11 | B13: 306 | C13: 30 | D13: 11,10 | E13: 2025-07-27T18:30:28.386Z | F13: 2025-07-27T18:30:28.386Z | G13: =VLOOKUP(B13,tasks!B13:C85,2,FALSE) -> computer_programmers_11 | H13: =LEFT(G13,FIND("_"&RIGHT(G13,LEN(G13)-FIND("@",SUBSTITUTE(G13,"_","@",LEN(G13)-LEN(SUBSTITUTE(G13,"_",""))))),G13)-1) -> computer_programmers | I13: TRUE
A14: 12 | B14: 307 | C14: 30,26 | D14: 11 | E14: 2025-07-27T18:30:38.678Z | F14: 2025-07-27T18:30:38.678Z | G14: =VLOOKUP(B14,tasks!B14:C86,2,FALSE) -> computer_programmers_12 | H14: =LEFT(G14,FIND("_"&RIGHT(G14,LEN(G14)-FIND("@",SUBSTITUTE(G14,"_","@",LEN(G14)-LEN(SUBSTITUTE(G14,"_",""))))),G14)-1) -> computer_programmers | I14: TRUE
A15: 13 | B15: 308 | C15: 30 | D15: 11 | E15: 2025-07-27T18:30:45.873Z | F15: 2025-07-27T18:30:45.873Z | G15: =VLOOKUP(B15,tasks!B15:C87,2,FALSE) -> computer_programmers_13 | H15: =LEFT(G15,FIND("_"&RIGHT(G15,LEN(G15)-FIND("@",SUBSTITUTE(G15,"_","@",LEN(G15)-LEN(SUBSTITUTE(G15,"_",""))))),G15)-1) -> computer_programmers | I15: TRUE
A16: 14 | B16: 309 | C16: 30,27 | D16: 11 | E16: 2025-07-27T18:30:57.492Z | F16: 2025-07-27T18:30:57.492Z | G16: =VLOOKUP(B16,tasks!B16:C88,2,FALSE) -> computer_programmers_14 | H16: =LEFT(G16,FIND("_"&RIGHT(G16,LEN(G16)-FIND("@",SUBSTITUTE(G16,"_","@",LEN(G16)-LEN(SUBSTITUTE(G16,"_",""))))),G16)-1) -> computer_programmers | I16: TRUE
A17: 15 | B17: 310 | C17: 30 | D17: 11 | E17: 2025-07-27T18:31:03.746Z | F17: 2025-07-27T18:31:03.746Z | G17: =VLOOKUP(B17,tasks!B17:C89,2,FALSE) -> computer_programmers_15 | H17: =LEFT(G17,FIND("_"&RIGHT(G17,LEN(G17)-FIND("@",SUBSTITUTE(G17,"_","@",LEN(G17)-LEN(SUBSTITUTE(G17,"_",""))))),G17)-1) -> computer_programmers | I17: TRUE
A18: 16 | B18: 311 | C18: 30,26 | D18: 11 | E18: 2025-07-27T18:31:11.147Z | F18: 2025-07-27T18:31:11.147Z | G18: =VLOOKUP(B18,tasks!B18:C90,2,FALSE) -> computer_programmers_16 | H18: =LEFT(G18,FIND("_"&RIGHT(G18,LEN(G18)-FIND("@",SUBSTITUTE(G18,"_","@",LEN(G18)-LEN(SUBSTITUTE(G18,"_",""))))),G18)-1) -> computer_programmers | I18: TRUE
A19: 36 | B19: 332 | C19: 26,29 | D19: 10,7 | E19: 2025-07-27T18:34:08.570Z | F19: 2025-07-27T18:34:08.570Z | G19: =VLOOKUP(B19,tasks!B19:C110,2,FALSE) -> operations_1 | H19: =LEFT(G19,FIND("_"&RIGHT(G19,LEN(G19)-FIND("@",SUBSTITUTE(G19,"_","@",LEN(G19)-LEN(SUBSTITUTE(G19,"_",""))))),G19)-1) -> operations | I19: TRUE
A20: 37 | B20: 333 | C20: 26 | D20: 10 | E20: 2025-07-27T18:34:16.205Z | F20: 2025-07-27T18:34:16.205Z | G20: =VLOOKUP(B20,tasks!B20:C111,2,FALSE) -> operations_2 | H20: =LEFT(G20,FIND("_"&RIGHT(G20,LEN(G20)-FIND("@",SUBSTITUTE(G20,"_","@",LEN(G20)-LEN(SUBSTITUTE(G20,"_",""))))),G20)-1) -> operations | I20: TRUE
A21: 38 | B21: 334 | C21: 29 | D21: 8 | E21: 2025-07-27T18:34:24.821Z | F21: 2025-07-27T18:34:24.821Z | G21: =VLOOKUP(B21,tasks!B21:C112,2,FALSE) -> operations_3 | H21: =LEFT(G21,FIND("_"&RIGHT(G21,LEN(G21)-FIND("@",SUBSTITUTE(G21,"_","@",LEN(G21)-LEN(SUBSTITUTE(G21,"_",""))))),G21)-1) -> operations | I21: FALSE
A22: 39 | B22: 335 | C22: 26 | D22: 7 | E22: 2025-07-27T18:34:30.443Z | F22: 2025-07-27T18:34:30.443Z | G22: =VLOOKUP(B22,tasks!B22:C113,2,FALSE) -> operations_4 | H22: =LEFT(G22,FIND("_"&RIGHT(G22,LEN(G22)-FIND("@",SUBSTITUTE(G22,"_","@",LEN(G22)-LEN(SUBSTITUTE(G22,"_",""))))),G22)-1) -> operations | I22: TRUE
A23: 40 | B23: 336 | C23: 27,26 | D23: 9 | E23: 2025-07-27T18:34:37.796Z | F23: 2025-07-27T18:34:37.796Z | G23: =VLOOKUP(B23,tasks!B23:C114,2,FALSE) -> operations_5 | H23: =LEFT(G23,FIND("_"&RIGHT(G23,LEN(G23)-FIND("@",SUBSTITUTE(G23,"_","@",LEN(G23)-LEN(SUBSTITUTE(G23,"_",""))))),G23)-1) -> operations | I23: TRUE
A24: 41 | B24: 337 | C24: 29 | D24: 8 | E24: 2025-07-27T18:34:45.381Z | F24: 2025-07-27T18:34:45.381Z | G24: =VLOOKUP(B24,tasks!B24:C115,2,FALSE) -> operations_6 | H24: =LEFT(G24,FIND("_"&RIGHT(G24,LEN(G24)-FIND("@",SUBSTITUTE(G24,"_","@",LEN(G24)-LEN(SUBSTITUTE(G24,"_",""))))),G24)-1) -> operations | I24: FALSE
A25: 42 | B25: 338 | C25: 29,26 | D25: 10 | E25: 2025-07-27T18:34:53.405Z | F25: 2025-07-27T18:34:53.405Z | G25: =VLOOKUP(B25,tasks!B25:C116,2,FALSE) -> operations_7 | H25: =LEFT(G25,FIND("_"&RIGHT(G25,LEN(G25)-FIND("@",SUBSTITUTE(G25,"_","@",LEN(G25)-LEN(SUBSTITUTE(G25,"_",""))))),G25)-1) -> operations | I25: TRUE
A26: 43 | B26: 339 | C26: 26 | D26: 10 | E26: 2025-07-27T18:35:04.471Z | F26: 2025-07-27T18:35:04.471Z | G26: =VLOOKUP(B26,tasks!B26:C117,2,FALSE) -> operations_8 | H26: =LEFT(G26,FIND("_"&RIGHT(G26,LEN(G26)-FIND("@",SUBSTITUTE(G26,"_","@",LEN(G26)-LEN(SUBSTITUTE(G26,"_",""))))),G26)-1) -> operations | I26: TRUE | J26: 10 | K26: 26
A27: 44 | B27: 340 | C27: 26,27 | D27: 10 | E27: 2025-07-27T18:35:13.413Z | F27: 2025-07-27T18:35:13.413Z | G27: =VLOOKUP(B27,tasks!B27:C118,2,FALSE) -> operations_9 | H27: =LEFT(G27,FIND("_"&RIGHT(G27,LEN(G27)-FIND("@",SUBSTITUTE(G27,"_","@",LEN(G27)-LEN(SUBSTITUTE(G27,"_",""))))),G27)-1) -> operations | I27: TRUE
A28: 45 | B28: 341 | C28: 26 | D28: 7 | E28: 2025-07-27T18:35:20.202Z | F28: 2025-07-27T18:35:20.202Z | G28: =VLOOKUP(B28,tasks!B28:C119,2,FALSE) -> operations_10 | H28: =LEFT(G28,FIND("_"&RIGHT(G28,LEN(G28)-FIND("@",SUBSTITUTE(G28,"_","@",LEN(G28)-LEN(SUBSTITUTE(G28,"_",""))))),G28)-1) -> operations | I28: TRUE
A29: 46 | B29: 342 | C29: 27 | D29: 10 | E29: 2025-07-27T18:35:27.212Z | F29: 2025-07-27T18:35:27.212Z | G29: =VLOOKUP(B29,tasks!B29:C120,2,FALSE) -> operations_11 | H29: =LEFT(G29,FIND("_"&RIGHT(G29,LEN(G29)-FIND("@",SUBSTITUTE(G29,"_","@",LEN(G29)-LEN(SUBSTITUTE(G29,"_",""))))),G29)-1) -> operations | I29: TRUE
A30: 47 | B30: 343 | C30: 27 | D30: 9 | E30: 2025-07-27T18:35:36.062Z | F30: 2025-07-27T18:35:36.062Z | G30: =VLOOKUP(B30,tasks!B30:C121,2,FALSE) -> operations_12 | H30: =LEFT(G30,FIND("_"&RIGHT(G30,LEN(G30)-FIND("@",SUBSTITUTE(G30,"_","@",LEN(G30)-LEN(SUBSTITUTE(G30,"_",""))))),G30)-1) -> operations | I30: FALSE
A31: 48 | B31: 344 | C31: 27 | D31: 10 | E31: 2025-07-27T18:35:48.828Z | F31: 2025-07-27T18:35:48.828Z | G31: =VLOOKUP(B31,tasks!B31:C122,2,FALSE) -> operations_15 | H31: =LEFT(G31,FIND("_"&RIGHT(G31,LEN(G31)-FIND("@",SUBSTITUTE(G31,"_","@",LEN(G31)-LEN(SUBSTITUTE(G31,"_",""))))),G31)-1) -> operations | I31: TRUE
A32: 49 | B32: 345 | C32: 26 | D32: 10,7 | E32: 2025-07-27T18:36:01.112Z | F32: 2025-07-27T18:36:01.112Z | G32: =VLOOKUP(B32,tasks!B32:C123,2,FALSE) -> operations_16 | H32: =LEFT(G32,FIND("_"&RIGHT(G32,LEN(G32)-FIND("@",SUBSTITUTE(G32,"_","@",LEN(G32)-LEN(SUBSTITUTE(G32,"_",""))))),G32)-1) -> operations | I32: TRUE
A33: 50 | B33: 346 | C33: 27 | D33: 9 | E33: 2025-07-27T18:36:10.070Z | F33: 2025-07-27T18:36:10.070Z | G33: =VLOOKUP(B33,tasks!B33:C124,2,FALSE) -> marketing_0 | H33: =LEFT(G33,FIND("_"&RIGHT(G33,LEN(G33)-FIND("@",SUBSTITUTE(G33,"_","@",LEN(G33)-LEN(SUBSTITUTE(G33,"_",""))))),G33)-1) -> marketing | I33: TRUE
A34: 51 | B34: 347 | C34: 26 | D34: 7 | E34: 2025-07-27T18:36:23.460Z | F34: 2025-07-27T18:36:23.460Z | G34: =VLOOKUP(B34,tasks!B34:C125,2,FALSE) -> marketing_2 | H34: =LEFT(G34,FIND("_"&RIGHT(G34,LEN(G34)-FIND("@",SUBSTITUTE(G34,"_","@",LEN(G34)-LEN(SUBSTITUTE(G34,"_",""))))),G34)-1) -> marketing | I34: FALSE | M34: 1. TASK : have subtask, its from same domain person
A35: 52 | B35: 348 | C35: 27,26 | D35: 9 | E35: 2025-07-27T18:36:31.760Z | F35: 2025-07-27T18:36:31.760Z | G35: =VLOOKUP(B35,tasks!B35:C126,2,FALSE) -> marketing_3 | H35: =LEFT(G35,FIND("_"&RIGHT(G35,LEN(G35)-FIND("@",SUBSTITUTE(G35,"_","@",LEN(G35)-LEN(SUBSTITUTE(G35,"_",""))))),G35)-1) -> marketing | I35: TRUE
A36: 53 | B36: 349 | C36: 27 | D36: 9 | E36: 2025-07-27T18:36:41.297Z | F36: 2025-07-27T18:36:41.297Z | G36: =VLOOKUP(B36,tasks!B36:C127,2,FALSE) -> marketing_4 | H36: =LEFT(G36,FIND("_"&RIGHT(G36,LEN(G36)-FIND("@",SUBSTITUTE(G36,"_","@",LEN(G36)-LEN(SUBSTITUTE(G36,"_",""))))),G36)-1) -> marketing | I36: TRUE
A37: 54 | B37: 350 | C37: 29,27 | D37: 9 | E37: 2025-07-27T18:36:49.883Z | F37: 2025-07-27T18:36:49.883Z | G37: =VLOOKUP(B37,tasks!B37:C128,2,FALSE) -> marketing_5 | H37: =LEFT(G37,FIND("_"&RIGHT(G37,LEN(G37)-FIND("@",SUBSTITUTE(G37,"_","@",LEN(G37)-LEN(SUBSTITUTE(G37,"_",""))))),G37)-1) -> marketing | I37: TRUE
A38: 55 | B38: 351 | C38: 27 | D38: 9 | E38: 2025-07-27T18:36:59.382Z | F38: 2025-07-27T18:36:59.382Z | G38: =VLOOKUP(B38,tasks!B38:C129,2,FALSE) -> marketing_6 | H38: =LEFT(G38,FIND("_"&RIGHT(G38,LEN(G38)-FIND("@",SUBSTITUTE(G38,"_","@",LEN(G38)-LEN(SUBSTITUTE(G38,"_",""))))),G38)-1) -> marketing | I38: TRUE | J38: 27 | K38: 9
A39: 56 | B39: 352 | C39: 27 | D39: 9,7 | E39: 2025-07-27T18:37:05.840Z | F39: 2025-07-27T18:37:05.840Z | G39: =VLOOKUP(B39,tasks!B39:C130,2,FALSE) -> marketing_7 | H39: =LEFT(G39,FIND("_"&RIGHT(G39,LEN(G39)-FIND("@",SUBSTITUTE(G39,"_","@",LEN(G39)-LEN(SUBSTITUTE(G39,"_",""))))),G39)-1) -> marketing | I39: TRUE
A40: 57 | B40: 353 | C40: 26 | D40: 10 | E40: 2025-07-27T18:37:11.888Z | F40: 2025-07-27T18:37:11.888Z | G40: =VLOOKUP(B40,tasks!B40:C131,2,FALSE) -> marketing_8 | H40: =LEFT(G40,FIND("_"&RIGHT(G40,LEN(G40)-FIND("@",SUBSTITUTE(G40,"_","@",LEN(G40)-LEN(SUBSTITUTE(G40,"_",""))))),G40)-1) -> marketing | I40: FALSE
...

Sheet tasks
B1: ID | C1: Deepflow ID | D1: Required Skills | E1: Sector | F1: Tags | G1: Manpower Needed | H1: Roles Required | I1: Estimated Time | J1: Embedding | K1: Created At
A2: 0 | B2: 295 | C2: computer_programmers_0 | D2: Programming,Workflow Chart Creation,Diagram Analysis,Computer Science Knowledge,Symbolic Logic | E2: Software Development | F2: Program Analysis,Software Review,Workflow Design | G2: 1 | H2: Software Developer | I2: 8 | J2: [0.008025651,-0.012875193,0.0051227557,-0.024397977,0.0029046026,0.007984668,-0.032758314,0.0040128254,0.00013287147,-0.022075662,0.013578718,0.00039551943,0.002366713,0.012335596,-0.008380828,-0.00033852877,0.002786779,-0.0071991794,0.008100784,-0.014767197,-0.023400748,0.025190298,0.002737259,-0.01242439,-0.016174247,0.032758314,0.011625241,-0.050790414,0.003684969,0.0055394066,0.018728795,-0.02065495,0.011693544,-0.025477171,-0.02304557,-0.010587028,-0.0032051373,0.0012465372,0.0056725983,-0.012178497,0.023004588,0.018537546,-0.012882023,-0.01804576,-0.0014582778,0.010266002,-0.0026416343,-0.0092414515,-0.005792129,0.017840851,-0.0057238257,0.0036098352,-0.026009938,0.008326186,0.007957347,0.005430121,0.0062429314,0.01323037,0.0053584026,-0.022171287,0.004186999,0.0045626676,-0.0137699675,-0.013462602,0.0015607328,-0.01261564,-0.0026296813,0.024356995,0.011379348,-0.009719575,0.039342765,0.029589036,-0.01883808,0.009582968,0.027348684,-0.004596819,-0.004364588,-0.0014360792,-0.0029746133,0.0328676,0.012601979,-0.016146926,-0.0063419715,0.010361627,0.0072879735,-0.004589989,-0.011734526,0.011734526,-0.009029711,-0.0018100403,-0.0044397213,0.0112359105,0.021597538,0.0052115503,0.0016939245,-0.009787878,-0.011604749,0.027840469,0.0043372666,-0.045845248,-0.0030548698,0.008797479,-0.018715134,-0.0049110153,-0.01961674,-0.022977266,-0.0038318213,-0.014931125,0.0328676,-0.0240428,-0.02763556,0.03483474,-0.004989564,-0.0019449396,0.013305504,-0.017594958,0.022471821,-0.027116453,0.00027598845,-0.031310283,0.017021209,0.012595149,0.021925393,-0.016707014,0.02066861,0.03144689,-0.007738776,-0.016310854,-0.010798769,-0.016857281,0.0059184902,-0.0064205206,0.012888853,0.0124175595,-0.008776988,0.0019381092,-0.021010129,0.043960072,-0.0025135654,-0.017540315,0.005778468,0.012601979,-0.0007846354,-0.010006449,-0.004163093,0.006256592,0.015791748,0.0122468015,0.0069020595,-0.018441921,-0.009931316,-0.012731755,0.027717523,-0.001000645,-0.0070352512,0.00701476,-0.014166127,0.00036051392,-0.0034629828,-0.0010774863,-0.008858952,0.016187908,-0.020313434,-1.0565684e-05,-0.004272378,0.01543657,0.009487343,0.00902288,-0.006649337,-0.005938981,-0.017253442,0.013879253,-0.03185671,0.0021464345,0.011898453,0.0038352364,-0.007096724,-0.009931316,-0.025436189,-0.005689674,-0.00084995053,-0.010395778,0.010641671,0.0059184902,-0.033796526,-0.0013754598,0.038987584,-0.014958447,0.01743103,-0.0106143495,0.010791939,0.019398168,-0.0075406963,0.002704815,-0.6574613,-0.020354416,-0.0064410116,-0.021460932,0.023906194,0.011905284,0.010682653,0.011502294,-0.0073221256,0.019507453,0.034944024,0.017349066,0.009931316,0.00883163,-0.010505064,-0.02263575,-0.010908054,-0.047648456,0.0110446615,0.028004397,-0.01021819,0.005587219,-0.015463891,-0.011290553,-0.009439531,0.0067347162,0.028687432,0.0041221105,0.0075611873,0.011119795,-0.0077251154,0.008121275,0.0061848736,-0.014739876,0.061636996,0.0025203957,-0.0075065447,0.011556936,0.028359575,0.024575567,-0.032949563,-0.010429931,0.007895874,0.025067352,-0.010750957,0.023086552,0.021788787,-0.00400258,-0.012335596,-0.012882023,0.010867072,-0.02006754,-0.004159678,0.036801875,0.005969718,0.0050442065,0.0149721075,-0.016529424,0.0058843386,0.006075588,0.011106134,0.0143710375,-0.034725454,0.0036234958,-0.006430766,0.019343525,-0.024616549,-0.023031909,-0.012158006,0.004070883,0.011679883,-0.0017639356,-0.0030719459,-0.012301444,-0.012369747,0.03308617,0.018974686,-0.0041801687,0.0010057677,-0.00018185783,-0.0016247673,0.016980227,-0.0050783586,-0.017909154,0.028960645,0.0044260607,-0.016925585,-0.021966375,0.0110651525,-0.0004836735,0.02666565,0.023619318,-0.003285394,-0.018400937,0.0021105753,0.02225325,-0.010368457,0.012082873,0.0014821839,-0.025477171,-0.015491213,-0.026993508,-0.007301634,-0.0039342763,0.016324515,0.0075270357,-0.030627249,-0.0022915793,0.03409706,-0.0019517699,0.0026074827,-0.014958447,-0.001358384,-0.00822373,0.007513375,-0.029343145,0.005293514,-0.011611579,-0.0025835764,-0.02866011,-0.0022266912,-0.0019398167,0.006591279,-0.018182367,0.0025818688,0.018346295,-0.014603268,0.002482829,-0.0016187908,0.008114445,0.0025921143,0.00045720593,-0.0020866692,0.0038898792,-0.007328956,-0.022102984,0.008032481,0.0002576319,-0.016338175,-0.037211698,-0.017116833,-0.006031191,-0.0015624404,-0.011078813,0.0031880615,-0.029671,-0.035709023,0.005354987,0.00961029,0.021419948,-0.008633551,0.0037259508,-0.020914504,0.045380786,0.012977648,-0.013244031,0.015245321,-0.0058775083,-0.012998139,-0.025422528,0.0016409894,-0.0015880542,-0.029179215,-0.012349256,0.011283723,-0.00092038844,-0.002976321,0.009220961,-0.011106134,-0.029479751,-0.0053413264,0.006871323,-0.015518534,0.0028294688,-0.0033827263,0.016707014,-0.008531095,0.0006155845,0.0064239358,-0.015177017,-0.0048666177,0.004607065,-0.025873331,-0.02285432,0.016406478,0.012499523,0.028359575,0.026802257,0.004210905,-0.0010305276,-0.011112965,0.022280572,0.0077865887,-0.010723636,-0.019876292,0.033031527,-0.029124573,0.0028584977,-0.012082873,0.032157246,0.024807798,0.02284066,0.0022864565,0.012574658,0.011802829,-0.029616358,0.013599209,-0.028113684,0.015942015,0.010949036,0.008114445,-0.003037794,-0.0020815465,0.005225211,0.0130391205,0.0006292451,-0.016966566,0.012957157,-0.017881833,0.0029421693,0.008367168,-0.01363336,0.018510224,-0.024725834,0.024152085,0.01863317,-0.0004887963,0.027799487,-0.013203049,-0.027143775,-0.013879253,0.0014070502,0.006468333,0.0063214805,0.008503774,0.033960454,-0.00450461,-0.03308617,0.03223921,0.022116644,-0.015149696,-0.0033571126,0.025081012,-0.03669259,0.019657722,-0.000881114,0.052948803,0.0113656875,-0.022881642,-0.009705914,-0.012533676,0.0065093148,-0.003828406,0.021119414,0.018346295,-0.003387849,0.03390581,0.0098425215,0.018810758,0.031829387,-0.00020288247,0.02284066,0.009507835,0.019971916,-0.018783437,-0.015163356,-0.014767197,-0.014876482,-0.008087124,0.00345786,0.016064962,0.0014830377,-0.0060243607,0.01823701,-0.01142716,-0.0026091903,0.011078813,0.0095419865,0.016310854,0.008018821,-0.0018305314,0.002462338,0.0077865887,0.028796718,0.0068747383,-0.010703144,0.009760557,-0.0015965921,-0.00084909674,0.010873903,-0.0016435508,0.0118369805,0.011570597,0.02285432,-0.008770158,-0.015737105,0.02786779,-0.0069259657,-0.020613968,0.0029489996,-0.0029285087,0.016488442,-0.0016981935,-0.037840087,0.036118843,0.0007308465,-0.012513184,-0.0044704583,-0.0136196995,-0.004525101,0.00902288,0.009043371,-0.0024606304,-0.0029404617,-0.010962697,-0.011727695,-0.0100132795,-0.0012439758,0.016119605,0.029233858,-0.022717714,-0.0083398465,-0.007397259,0.01022502,0.0740409,0.01463059,0.0040811286,0.016078623,-0.014002198,-0.0074109198,-0.049970772,-0.024425298,0.026009938,-0.015668802,0.020026559,-0.00781391,0.009664932,-0.031802066,-0.0041733384,-0.00073468854,0.009733235,0.0055598975,-0.0011620118,-0.023373427,-0.00450461,-0.031009747,0.02665199,-0.008401319,-0.001021136,0.0133396555,0.02644708,0.049588274,-0.02143361,-0.03390581,-0.0049110153,0.036637947,-0.010566537,0.020613968,-0.003951352,0.062456638,0.029233858,0.046801496,0.0110446615,-0.004665123,0.016406478,0.014275412,0.014616929,-0.025121994,0.014562286,0.009043371,-0.0052183806,0.022922624,-0.012082873,-0.023933515,0.0031436644,0.01022502,-0.0033536972,0.013278183,0.018769776,0.028878681,-0.00092892634,0.003046332,0.004460213,-0.028550824,-0.022198608,-0.010429931,0.019152276,-0.0073221256,0.012970817,-0.007048912,0.009801539,-0.007875383,-0.025162976,0.013865592,-0.0122672925,-0.014357377,-0.011386178,-0.0136401905,0.0089409165,0.008572077,0.01022502,-0.00881797,-0.009972298,-0.005775053,-0.047757745,-0.046364352,-0.015463891,-0.0052183806,-0.016174247,0.012123855,-0.02846886,-0.0023632979,-0.004251887,0.004508025,-0.0033980946,-0.009760557,-0.014261751,-0.013489923,-0.012164837,0.017171476,0.017868172,0.014808179,0.0074450714,-0.017622279,-0.008934086,-0.026720293,-0.0033246684,-0.0070215906,0.015559517,-0.0018749286,-0.0060585123,-0.00761583,-0.0236603,-0.0033998021,0.019042991,-0.006287329,0.032184567,-0.002923386,0.029780285,0.031829387,0.016119605,-0.0075885085,0.022594767,-0.026365116,-0.009596629,-0.005771638,0.02162486,0.04043562,-0.018346295,0.02405646,0.008688194,-0.013435281,-0.0017724734,0.0038557274,-0.01041627,0.017103173,-0.0097127445,-0.020559326,-0.00057673693,-0.009603459,-0.00042796353,0.002272796,-0.01825067,-0.0017963797,-0.013305504,0.028878681,0.026132884,-0.010347966,0.003999165,-0.03289492,0.0038557274,-0.0010971235,-0.021406287,0.0074792234,0.009057032,0.0054676877,-0.027362345,0.004528516,0.00031846465,-0.02463021,-0.020695932,-0.007069403,0.014084163,0.03221189,0.003975258,-0.008852121,0.013086933,-0.0072060097,-0.008367168,-0.00027235984,0.010081583,-0.0057613924,-0.035599735,0.010279663,0.02805904,-0.0009127043,0.0013993661,-0.009248282,0.030709213,0.026037259,-0.0022864565,-0.011761847,-0.0010441884,-0.019794328,-0.009528326,0.016078623,0.0061165704,-0.0037122902,-0.033823848,0.009869843,0.019521113,0.01463059,0.0011107841,0.020982808,0.020586647,-0.0066390913,0.0039035399,0.01142716,0.026228508,-0.01861951,-0.0027287211,-0.04133722,0.010901224,0.02304557,0.008046142,0.016201569,0.021010129,0.009637611,-0.003244412,0.011597918,-0.014466662,-0.012403899,0.025559135,-0.02986225,0.003807915,-0.023837889,-0.009835691,-0.0114135,0.0056452765,0.00883163,0.008858952,0.029015288,-0.0010826091,-0.030900462,0.01684362,-0.033523314,0.049861487,0.0028004397,0.052156482,0.032102603,0.033140812,-0.016939245,-0.016146926,0.0067381314,-0.008578908,0.013503584,0.030354034,8.975495e-05,-0.013052781,0.00066382374,0.0011082228,-0.0027645805,-0.03346867,-0.0001445044,-0.0012038476,0.004668538,-0.013264522,0.013257692,-0.027294042,0.02885136,0.0002544302,-0.012055552,0.0038830487,-0.014302733,-0.0057579773,0.0048188055,-0.03065457,0.021570217,-0.00051910593,-0.008749667,0.007192349,-0.0005664914,-0.016256211,0.003848897,0.017362727,-0.008312525,-0.0032256285,0.006727886,0.022731375,0.01646112,-0.015491213,-0.003746442,0.014193448,0.029370466,-0.0015778088,-0.014644251,-0.021693163,0.0067620375,0.023168515,-0.010245511,-0.012560997,-0.042184185,-0.011707204,-0.0034817662,0.015108714,-0.011625241,0.025941635,0.0010151594,0.00781391,0.00038100494,0.023305124,-0.0012952033,0.013776798,-0.044615787,0.007315295,0.010505064,0.008018821,0.011727695,0.0036815538,-0.02644708,0.0089409165,0.031091712,-0.0014762074,0.011768677,0.0052422867,0.00070694025,-0.027430648,0.011352027,-0.027430648,-0.025900653,0.04248472,-0.008647212,-0.019152276,-0.0075065447,0.0014514474,0.009057032,-0.019534774,-0.011577427,0.0017639356,-0.0060619274,-0.0052422867,-0.016064962,-0.0122672925,0.0050442065,-0.01721246,-0.012841041,0.021460932,-0.013496754,0.01142716,0.007977838,0.0028602052,-0.006748377,-0.035162594,-0.020299774,0.002923386,0.011741356,-0.013483093,-0.008756497,0.0023615903,0.017895494,-0.018510224,0.0036337413,-0.012888853,-0.02584601,0.0048392965,0.009999619,0.015600499,0.018551206,-0.023837889,-0.021310663,-0.015190678,-0.014753536,-0.027020829,0.0078002494,-0.016720675,0.020518344,0.023878872,-0.0071786884,-0.04232079,-0.03128296,-0.041801687,-0.046173103,-0.0071035544,-0.0029250935,0.013927065,0.02064129,0.007895874,0.01122908,-0.021064771,0.006154137,-0.008975068,-0.0038659729,0.0053413264,0.008346677,0.020805217,-0.009036541,0.015928354,-0.036446698,0.010580198,0.005549652,-0.0044192304,-0.0140705025,-0.03464349,-0.023947176,-0.021788787,-0.004805145,-0.0023035326,0.016297193,0.016488442,-0.018086743,0.014193448,0.00097588496,-0.01823701,-0.023400748,0.00016745008,-0.020313434,-0.0032187982,0.0010527263,0.0013327702,-0.007253822,-0.011918944,-0.0021805863,0.012164837,-0.006167798,0.002296702,0.035982236,0.008052972,0.0018680983,-0.010949036,-0.018687813,-0.019097634,-0.011406669,-0.010081583,-0.030818498,0.0025255184,-0.027731184,0.0068986444,-0.016898263,-0.005430121,-0.0196304,0.008367168,-0.030299392,0.015764426,0.0057374863,0.024111103,0.0037020447,-0.0002486671,-0.017731564,-0.016993888,-0.014862821,-0.0015846391,0.0039137853,-0.0026296813,0.004767578,-0.017622279,0.007772928,-0.0045011947,0.026843239,-0.026938865,0.01081926,0.2006481,-0.007943686,0.004344097,0.017936476,0.014097824,0.012151176,0.037129734,0.017157815,-0.0018868817,0.009555647,0.008995559,0.010272833,-0.041583113,-0.008169088,-0.0030343789,-0.013435281,-0.014043181,-0.03147421,-0.014043181,-0.010655331,0.028605467,-0.0010817553,-0.0063692927,-0.017253442,0.015696123,0.03147421,-0.017608618,0.021447271,0.03199332,0.02225325,-0.015108714,0.0034271234,-0.008189579,0.009678593,0.009118505,-0.0003726805,0.026187526,-0.0038215758,0.017280763,-0.031392246,-0.010484573,-0.0009938146,0.014043181,-0.034370273,0.008913595,0.019480132,-0.008169088,-0.021884412,0.0034527374,0.009692254,-0.0027987321,0.015532195,0.029889572,0.040708832,0.0061814585,0.011106134,-0.015969336,0.005638446,-0.0036542322,5.2775056e-05,-0.0164338,0.013653851,-0.010102074,-0.0064068595,-0.012533676,-0.019425489,-0.002564793,0.012226311,0.011522785,-0.01782719,-0.016870942,-0.027239399,-0.0052388716,-0.011659392,-0.026187526,-0.01763594,0.048003636,0.045162212,0.002749212,0.031173676,-0.011461312,-0.018906383,-0.030326713,-0.033769205,0.0023632979,0.00059253204,0.04324972,0.016297193,-0.015545856,0.0053788936,-0.020299774,0.009876673,-0.029097252,0.0020047051,-0.0013882668,0.011891623,0.0026740783,-0.0002469595,-0.0154229095,0.015368267,-0.022471821,0.066991985,0.016283533,0.03508063,-0.019206919,0.010136226,0.002873866,0.014439341,0.013141576,-0.008886273,-0.0051398315,-0.005068113,0.014166127,0.0031709857,-0.01182332,0.018592188,0.00013799423,-0.017472012,-0.013660681,0.007438241,0.012007739,-0.0009374643,-0.0035312863,0.013305504,0.0033554048,-0.011338366,-0.018100403,0.0064990693,-0.009104844,-0.025695743,0.020518344,-0.032840278,-0.010696313,-0.0016307438,-0.012998139,-0.0077660973,-0.002588699,0.0046582925,0.0044977795,0.008879443,-0.0010928545,0.025914313,-0.008968238,0.004436306,0.009528326,0.012513184,0.009876673,0.004665123,-0.032539744,-0.03803134,-0.002716768,0.011877962,-0.0002828188,-0.013401128,0.03770348,-0.0020149506,-0.023960836,-0.011085643,-0.0030531622,0.0033485745,-0.030135464,0.011406669,0.046255067,0.017157815,-0.0033366214,-0.011474973,-0.17682387,0.001774181,6.659582e-05,-0.016993888,0.030599928,0.008264712,0.021515574,0.014589608,-0.011474973,0.0126293,-0.004429476,-0.0017775962,-0.035599735,-0.007492884,0.015013089,0.0101635475,-0.009801539,0.04062687,0.024575567,0.0073631075,0.02006754,0.0019295713,6.0832725e-05,0.015682463,-0.009951807,0.008585738,-0.026488062,0.014357377,0.016993888,-0.006560542,0.0004273232,-0.002585284,0.00531059,-0.006290744,0.0038625577,-0.0030019348,-0.021542896,-0.024397977,-0.029971536,-0.006475163,0.02064129,0.03652866,0.003285394,-0.016338175,0.006840586,0.017553976,0.04152847,-0.013155237,0.0018117479,-0.0016025687,0.018701473,0.00029882742,0.0005173983,-0.022622088,0.0018971271,-0.0029046026,-0.0032409967,0.011249571,-0.036555983,-0.01101734,0.013271352,-0.021501914,-0.0038967095,0.0022079076,-0.013653851,0.0030036424,-0.018769776,0.023988158,0.002416233,-0.01704853,0.010402609,-0.017185137,-0.0026996923,-0.0009255112,0.009391719,-0.00170417,-0.018059421,0.009234621,0.025955295,-0.011317875,0.02103745,0.009398549,0.013203049,-0.013763137,0.017116833,-0.017116833,-0.0077524367,-0.010757787,-0.0029899818,-0.008476453,0.012321935,-0.020340756,-0.0168163,-0.009726405,0.024999047,-0.0021208208,-0.016297193,-0.012164837,0.006174628,-0.010375287,0.011317875,0.01659773,-0.023933515,-0.0018510224,0.023783246,0.026679311,0.01982165,0.015737105,0.041227937,0.014330055,-0.030135464,0.018988347,0.0103138145,0.019411828,0.0075611873,0.022021018,-0.0059082448,-0.0064580874,-0.0016999011,0.0049315062,0.047648456,0.029916894,0.014903803,0.010566537,0.001259344,0.007472393,-0.07469661,-0.022362536,0.006447842,0.027430648,-0.013974877,0.008722345,-0.016201569,0.015354606,0.000121558725,0.025518153,0.00025186883,-0.03204796,-0.022062002,-0.027020829,0.004463628,-0.00094002567,-0.01621523,-0.010730466,0.012601979,0.041255258,-0.009343906,-0.02065495,-0.0011543276,-0.010798769,-0.0019483548,0.02023147,-0.024425298,-0.008462792,0.022430839,0.0026740783,0.0047983145,-0.015778087,0.0131484065,-0.024001818,-0.006840586,0.0118164895,-0.022130305,-0.050134704,0.047047388,-0.025381546,0.0043816636,0.002885819,0.036118843,-0.034534205,-0.010006449,-0.0012977647,-0.023373427,0.010668992,-0.0053447415,-0.03308617,-0.036392055,-0.016857281,-0.04251204,-0.00900922,0.030599928,-0.020627629,0.0067347162,-0.0133191645,-0.008264712,0.01161841,-0.016406478,-0.0071035544,-0.007936856,0.005477933,-0.0022608428,-0.006553712,-0.019944595,-0.010129396,0.005495009,-0.022731375,-0.02263575,0.013325995,-0.025354225,0.023742264,-0.006096079,-0.005652107,-0.016488442,-0.0026279737,0.02004022,-0.0043372666,0.0073221256,-0.026009938,0.041173294,-0.003568853,0.027376005,0.021297002,-0.018059421,0.008087124,0.0082169,-0.02203468,0.021693163,0.006570788,0.014207109,-0.008968238,0.012909344,-0.031392246,0.011850641,-0.005826281,-0.01662505,0.021228699,-0.015149696,-0.023837889,-0.083603375,0.0078002494,-8.367167e-05,6.472815e-05,0.009145826,-0.0018766362,0.0064580874,-0.006837171,-0.0048153903,-0.0037259508,-0.02486244,-0.0008802602,-0.019165937,-0.0057852985,-0.009979128,0.0013054489,0.0120214,0.012943496,0.009330246,0.0005080066,-0.0025699157,-0.0047061048,0.0001445044,0.012076043,-0.010409439,0.0029097253,-0.012841041,0.0032461195,-0.01721246,-0.013660681,0.016488442,-0.015245321,0.017472012,0.03204796,-0.017690582,-0.005314005,-0.0007876237,0.012786398,0.037812766,0.045216855,-0.003568853,-0.03226653,0.0072674826,-0.020586647,-0.009002389,-0.020709593,0.0013600916,0.0009579553,0.015054071,-0.00076371746,0.003083899,0.0155731775,-0.0046753683,-0.020559326,-0.0028380067,-0.022772357,0.009268773,0.012902514,0.01704853,-0.008585738,0.022499142,0.0041050347,-0.0028106852,-0.019111294,-0.014780858,0.0021635105,-0.017075852,0.025750386,0.0026689556,-0.0013788751,-0.036610626,0.0004401301,-0.019575756,0.015149696,0.011153947,-0.006652752,-0.026788596,0.03322278,-0.013114254,0.00842181,0.0136196995,0.0139202345,-0.022704054,0.026597347,0.022676732,0.0011457896,-0.028113684,-0.022417178,-0.009746896,0.0122468015,-0.012144346,0.0052115503,-0.014876482,0.008647212,0.0033810188,0.010580198,-0.013291843,-0.013503584,0.002564793,0.021215038,-0.003787424,-0.014603268,0.0044226456,-0.009944976,-0.02583235,0.0015854929,-0.012642961,-0.019958256,-0.002725306,0.006130231,0.021597538,0.00033041774,0.0033536972,-0.007438241,-0.005959472,-0.011297383,-0.014138806,-0.02825029,-0.04087276,0.026214847,-0.030435998,-0.0023684206,0.020327095,-0.008838461,0.032321174,0.03729366,-0.0013370392,-0.030927783,0.005798959,-0.013196219,0.009671763,-0.0019090803,-0.016174247,0.004388494,-0.008237391,-0.0016896556,-0.030435998,-0.0007291389,-0.0041528475,0.07513375,0.023537355,-0.013756307,1.967725e-05,-0.024835119,0.0034390767,0.02906993,-0.0192479,0.01744469,-0.036118843,0.0377308,-0.009391719,0.0031060975,-0.019275222,-0.015682463,-0.012158006,-0.016911924,0.020299774,-0.0023154856,0.0065024844,-0.012499523,0.00701476,0.026324134,0.017786207,-0.029042609,-0.026952526,0.02042272,-0.008572077,0.003924031,-0.023305124,-0.021160396,0.019685043,-0.0116457315,-0.008544756,0.01682996,-0.0089614075,-0.0022813338,-0.013776798,0.012943496,0.02464387,0.011031001,0.014712554,-0.04106401,-0.027171096,-0.028441539,-0.011652562,-0.015982997,-0.0044021546,0.0018458996] | K2: 2025-07-27T18:28:47.883Z
A3: 1 | B3: 296 | C3: computer_programmers_1 | D3: Debugging,Problem-solving,Attention to detail,Knowledge of the programming language used | E3: Software Development | F3: Error Correction,Code Review,Quality Assurance | G3: 1 | H3: Developer | I3: 4 | J3: [-0.000316098,0.028327798,0.019661551,-0.017982466,-0.012207223,0.02767783,-0.032796334,-0.013229569,-0.008165231,-0.019011581,0.035883684,0.015247181,-0.0019075902,0.0075558852,-0.009370381,-0.03141515,0.022044769,0.01695335,-0.0014480421,-0.023642609,-0.031469315,0.01978342,-0.00895061,0.006106997,-0.00534193,0.013060307,-0.00869333,-0.046960235,-0.01805017,-0.009133413,0.026364353,-0.013398833,0.016479412,-0.020514635,-0.009113101,-0.0008145766,-0.01377121,-0.010169301,0.006740039,-0.0089302985,0.024143627,0.042004224,-0.011462468,0.004597174,0.017061677,0.023696773,-0.011002073,-0.016560659,-0.010196383,0.02632373,-0.010670318,-0.0019922215,-0.022952016,0.002960404,0.010460433,0.018348072,-0.0028825433,-0.0016181511,-0.009011544,-0.01871368,-0.013012913,-0.0015199787,0.0019262091,-0.007136114,-0.006327038,-0.012511896,0.0012973984,0.02927567,0.025660219,-0.017129382,0.028923605,-0.005531504,0.0076912954,0.008219395,0.014651376,-0.015490918,-0.018077252,0.0021242464,0.013344668,0.00922143,0.006750195,-0.0009876477,-0.03222761,0.019729257,-0.0013177098,0.011780681,-0.012274928,0.0131009305,0.008273559,-0.0082532475,-0.010629695,0.014245146,0.025348777,0.016005477,-0.0047698217,-0.010148989,-0.010785417,0.0355587,-0.02700078,-0.019499058,0.009979727,0.032688007,-0.030494362,-0.009058937,-0.017251251,-0.0067840475,0.007582967,-0.010013579,0.0077725416,-0.0048747645,-0.011604648,0.022302048,0.025375858,-0.022775983,0.0047765924,-0.0039912136,0.01390662,-0.002103935,-0.004851068,-0.02781324,0.019715715,0.027664289,0.0015826059,-0.021530211,-0.0016274605,0.014529507,-0.0021919515,-0.010304711,0.0010477359,-0.006469219,0.021408342,-0.002244423,0.025484186,0.007725148,-0.013622259,-0.008903216,-0.019228239,0.014989901,-0.01296552,-0.016899183,0.008280329,0.026107073,0.00045700918,0.005582283,0.009201119,0.0030128753,0.0069600805,0.022545787,0.023954052,-0.0040182956,0.0060968413,-0.0033700196,0.013324357,0.0102640875,0.0005357163,0.002879158,-0.0038117953,0.0024306118,-0.0100609725,-0.02418425,-0.009424545,0.00621871,0.0013244803,-0.014962819,-0.002406915,0.027352845,0.011746828,0.0009436393,0.007610049,-0.0051455847,-0.006780662,0.013574866,-0.028409045,0.019553224,0.015355509,0.0023087426,0.022004146,-0.0023679847,-0.021557292,-0.0014471958,0.012647307,-0.01618151,0.022098932,0.01149632,-0.011401533,0.0039742873,0.010853122,0.012213994,0.008219395,-0.012762405,0.031171411,0.014285768,-0.027244518,-0.025822712,-0.6621014,-0.032552596,-0.01737312,-0.008124608,-0.011956714,0.03461083,0.026269564,0.019404272,-0.0090318555,0.014177441,0.01818558,0.032254692,-0.018767845,-0.013473308,-0.015409673,-0.009553185,0.001745098,-0.045551967,0.016750233,0.02097503,-0.02606645,0.004945855,-0.010209924,-0.01911991,-0.0041909437,-0.00022173408,0.0055382745,-0.010128678,0.020609422,0.039079364,-0.010609384,0.007393393,0.017088758,0.008056902,0.062721975,-0.0037373195,0.0007392547,0.012647307,0.012708241,0.045254067,-0.018632434,-0.0018889713,0.022044769,0.031388067,0.0007984966,0.013392062,0.009986497,0.0044651492,-0.02419779,-0.0045125424,0.00962766,-0.019187616,-0.022437459,0.014800327,0.004664879,-0.012017649,0.011049466,-0.0145836705,0.013547784,-0.006993933,-0.010710942,0.031469315,-0.039648086,-0.0112932045,-0.024279036,0.0059478898,0.008463133,-0.010988532,-0.013717046,-0.016086724,-0.00057253096,-0.00641167,-0.016601281,0.01150309,-0.0015919154,0.047528956,0.022247884,0.0022359597,8.918026e-05,-0.0042010993,0.009729218,-0.021042734,-0.005118503,-0.010128678,0.016817939,0.0045125424,-0.016899183,-0.015721116,-0.0064861453,0.0001894684,0.021624997,-0.010135449,0.0046208706,-0.012511896,0.004891691,0.026960157,-0.01683148,0.0071835076,0.02352074,0.0016816246,-0.0050067897,0.00076887565,0.006736654,-0.0060392916,0.012654076,0.008097526,0.003163519,0.0035646716,0.022748902,0.013513931,0.001536905,-0.013689964,-0.0041774027,-0.0082871,0.019688632,-0.02540294,-0.006577547,0.010650007,5.8818776e-05,-0.020934407,0.0025270917,0.0072376714,0.022803066,-0.0029417851,-0.013060307,0.0046479525,-0.007853787,0.015842985,-0.002955326,-0.013439455,-0.001167066,0.00014895115,-0.020392766,-0.0023290543,-0.031902626,-0.007962116,0.007975657,-0.013243111,-0.010501056,-0.01991883,-0.002031152,-0.008720412,-0.0049797073,0.017562693,-0.0038659591,-0.021597916,-0.044847835,-0.0086053135,0.00040771143,0.0028537684,0.0034698846,0.017142922,-0.020893782,0.03610034,-0.0010756642,-0.012234305,0.005971587,-0.01349362,-0.015098229,-0.055897303,0.025145661,-0.008300641,-0.030358952,-0.01497636,0.0010968221,-0.011103631,0.005951275,0.016993972,-0.040270973,-0.026120614,-0.018686598,0.024617562,-8.473712e-05,0.0005399479,-0.004065689,0.018767845,-0.018767845,-0.007461098,0.01163173,-0.0044990014,0.01711584,0.006360891,-0.019675093,-0.020379225,0.029221507,-0.009309446,0.00654708,0.031442232,0.023344707,0.009322988,-0.024387365,-0.004299272,-0.0025964892,-0.0024543086,-0.008280329,0.030900592,-0.010121907,-0.0015445218,-0.02338533,0.044008292,0.024103003,-0.0017484833,0.019972995,-0.012782716,0.010927597,-0.02859862,0.0007743767,-0.010934368,0.015531542,-0.0035782126,-0.0027031247,-0.012471273,-0.013791522,-0.008117837,0.0151117705,0.028327798,-0.011828075,0.02314159,-0.019079287,-0.008456362,0.008774577,-0.0061036116,0.016790856,-0.026107073,0.022478081,0.01429931,0.0036831556,0.025782088,-0.0045125424,-0.0058327913,-0.0038795003,-0.002787756,0.012992602,0.0068077445,0.0152878035,0.017224168,0.012586372,-0.03100892,0.02900485,0.015179476,0.008828741,-0.0012550827,-0.010656777,-0.004928929,0.0049763224,0.018794926,0.051239192,0.0017239403,0.0066621783,0.006201784,-0.0058598733,0.00494924,0.0031262813,0.002198722,0.00088016584,0.022897853,0.022261426,0.007163196,0.030981837,0.03192971,0.0041096974,0.01924178,-0.010243776,0.0067298836,0.0024289193,0.0053148475,0.0065843174,-0.017657481,0.0016249216,-0.0066994163,0.008815199,-0.0019177459,-0.015842985,-0.013595177,0.0041909437,0.0070751794,-0.022356212,0.014922196,0.00048536068,0.0046039443,-0.015369049,-0.014326392,0.021868736,0.029708983,0.011604648,-0.0007980735,0.004539625,0.0027369773,-0.025470646,0.021719785,-0.0049560107,0.013974326,0.008097526,-0.0036120652,0.0059038815,-0.007779312,0.023222838,-0.012681158,-0.01336498,-0.026757041,-0.011333828,0.0030196458,-0.025037333,-0.003957361,0.03447542,0.004289116,-0.018740762,-0.01723771,0.0007595662,-0.01523364,0.00049001543,0.0010570453,-0.0073730815,0.0010892053,0.022220802,-0.024075922,-0.014732623,-0.021083357,0.012085354,0.026635172,-0.014258686,-0.02190936,0.021706244,0.012065043,0.08330431,0.015057607,-0.023480117,0.017996006,0.00655385,-0.0102844,-0.023913428,3.054662e-05,0.027163273,-0.024522774,-0.009262053,-0.0009842623,-0.005253913,-0.00420787,-0.006790818,0.0018449631,0.016452331,-0.013134782,-0.0138050625,0.004052148,0.005839562,-0.0046581086,0.013216029,-0.014367015,0.03339214,0.012119207,0.025633138,0.023493657,0.004441452,-0.0098849395,0.009180807,0.027447633,-0.011516632,0.0020565414,-0.010778646,0.070792414,0.0059952834,0.02044693,0.02205831,-0.015694033,0.013425915,-0.002901162,0.016425248,-0.0138795385,0.041110516,-0.00013974748,-0.0147597045,0.025998745,-0.039918907,-0.022735361,0.020243814,0.0030518058,0.001547907,0.0023967593,0.0054299464,0.0038964264,-0.0027792929,-0.003916738,-0.006079915,-0.05375782,-0.015044065,-0.018090794,-0.008761035,-0.003713623,-0.014732623,-0.0035443602,0.0015580629,-0.004099542,-0.033798367,-0.004539625,0.005057568,-0.025321694,-0.015991936,0.008111067,0.008713642,0.008327723,0.009424545,0.000761682,0.0013515623,-0.0033649418,-0.024766512,-0.03260676,0.011171335,-0.005545045,-0.0052606836,0.03155056,-0.0013769518,-0.01925532,-0.005589053,0.018117875,0.007244442,-1.3488118e-05,-0.00031948328,-0.0042315666,-0.01350716,0.0050203307,0.0050981916,0.014082653,0.014502425,-0.019444894,-0.0021276316,-0.049370535,-0.021963524,-0.009559955,0.008463133,0.008761035,-0.012342634,0.013243111,-0.004702117,-0.007921493,0.017833514,-0.02165208,0.01563987,0.012044731,-0.0013769518,0.025903957,0.015138852,0.009099561,0.013446226,-0.017535612,0.0009597193,-0.044983245,0.04208547,0.0411376,0.003490196,0.011516632,0.0076235905,-0.024143627,0.0018094179,0.010365645,-0.028381962,0.037237786,-0.024671726,-0.03062977,-0.010209924,-0.030711018,0.00030615384,0.012538978,-0.0061103823,-0.013019684,-0.0068415967,-0.0003708968,0.0015521386,0.003849033,0.03542329,-0.031090166,-0.01404203,0.0011916092,-0.01256606,0.041868813,-0.014949278,-0.000691438,-0.028950686,0.0024763127,-0.008408969,-0.021760408,0.00044854605,-0.022640573,0.027786158,0.031090166,-0.005037257,-7.5004515e-05,0.023331165,-0.0019295943,0.001693473,0.014339933,-0.005839562,0.0017019361,-0.008388657,0.00869333,0.014096195,-0.015531542,0.009153725,-0.01550446,0.0075152623,0.01095468,0.0064353663,-0.026418516,-0.0062085544,-0.02685183,-0.010358875,-0.020893782,0.0040893857,0.006831441,-0.019824043,0.018497024,0.02005424,0.004133394,-0.012640536,0.021665622,0.017197087,-0.0005340237,0.010291169,0.027258059,0.036560737,-0.023480117,-0.006909302,-0.02713619,0.00042231035,0.010291169,0.029519409,0.020487553,0.019539682,0.0011636808,-0.021949982,0.04213963,-0.012999373,-0.024915464,0.009647972,-0.016005477,-0.0102640875,-0.0010756642,0.014597212,0.01390662,0.017576234,0.0006237329,0.0018805081,0.018957417,0.0043500504,-0.028490292,-0.0008441975,0.0026675796,0.039187692,-0.005653373,0.012681158,0.041868813,0.009918792,-0.019729257,-0.0029180883,0.014502425,-0.013656111,0.028571537,0.026757041,0.0016401552,-0.0044008293,0.01203119,-0.0019177459,-0.013195717,-0.010270858,0.01844286,-0.0006749349,-0.0021614842,-0.011211959,0.015314885,-0.011211959,0.023344707,-0.011530173,0.02392697,-0.019282402,-0.014163899,-0.0033040072,0.014177441,-0.028138226,0.019756338,0.0049695517,0.0066994163,0.017454365,-0.01149632,-0.0074137044,0.012024419,-0.007582967,0.0050812652,-0.038835626,0.0026320345,0.016668987,0.021963524,-2.0708228e-05,-0.021692703,0.03006105,0.033852533,-0.013676423,-0.0126947,-0.0075355736,-0.007149655,0.0072512124,0.02193644,-0.019295944,-0.024956087,-0.013920161,-0.009146954,0.00855792,0.020081323,0.000929252,0.01203119,0.00013223646,-0.010223465,-0.01029794,-0.011685894,0.008496986,-0.026161237,-0.021381259,-0.0033141628,-0.0039505907,0.0021970293,0.012281699,0.0049424698,-0.017874137,0.015247181,-0.02165208,0.023507198,0.0035985243,-0.019715715,-0.014448261,-0.001607149,-0.017048135,-0.03447542,0.013317586,-0.038456477,-0.018253285,0.0020785455,-0.008036591,0.02018965,-0.003060269,-0.01109009,0.00069355377,-0.0021733325,0.013459767,-0.011733288,-0.023642609,0.026784124,-0.014515966,-0.013974326,0.016655445,-0.0061747017,-0.0042857304,0.004482075,-0.004918773,0.0020599265,-0.036154505,-0.020297978,-0.00801628,0.007921493,-0.035369124,-0.013067078,0.008219395,-0.011821304,-0.0052437573,0.024536315,-0.0017891063,-0.010399498,-0.017061677,0.009654743,0.00481383,0.030277705,-0.003050113,-0.004248493,-0.027054943,-0.012742093,-0.036831554,0.012227534,-0.040595956,0.033040073,0.012518667,-0.0098104635,-0.00042061773,-0.020501094,-0.013128012,-0.010216694,-0.009512561,-0.00095464144,0.02564668,0.024739431,-0.007298606,0.010433351,-0.015680494,0.014434719,-0.021205226,-0.007907951,0.015518001,0.0056330613,0.021855194,-0.0112932045,-0.0028097602,-0.00907925,-0.01082604,0.008564691,-0.013371751,-0.0043771323,-0.004810445,-0.016736692,-0.0018297294,0.00628303,0.013114471,-0.00108582,0.003568057,0.00052852265,-0.0031567486,0.0008425049,-0.01764394,0.0014268842,0.013046766,0.024441529,-0.024021758,0.01309416,-0.027867405,-0.003703467,0.010907286,-0.01431285,0.013825375,0.0055924384,-0.027664289,0.024400905,-0.006540309,-0.011002073,-0.0036526883,-0.022437459,-0.0021428652,0.000513289,-0.011516632,-0.012626994,-0.014664917,-0.015612788,-0.008104296,0.0040961565,0.0016917803,-0.023981133,-0.018009547,-0.03929602,0.008937068,-0.0016706225,0.0060054394,-0.016357543,-0.0021107055,-0.0070277858,0.008612084,-0.017982466,-0.013920161,-0.029194424,-0.010094825,0.0055585857,-0.018361613,-0.0003395832,-0.0129519785,0.031713054,-0.009417774,0.0038930413,0.19943205,-0.012058272,0.0007566041,0.026689336,-0.008774577,0.023304082,0.033365056,-0.008632395,-0.012491585,0.038293984,0.01911991,-0.008172002,-0.03409627,-0.0058767996,0.000788764,-0.0028046824,-0.03130682,-0.023290543,-0.018361613,-0.017318955,0.015071147,0.0044042147,-0.022098932,-0.012897815,0.040731367,0.0151117705,-0.019702174,0.017684562,0.040081397,0.0033717123,-0.02487484,-0.00400814,0.021096898,0.011239041,0.021191685,-0.008212624,0.018456401,-0.009512561,0.015314885,-0.010988532,0.011956714,0.0034021796,0.024008216,-0.0403793,-0.012329092,0.04211255,0.0022139556,-0.015409673,0.010115136,0.023588445,-0.014177441,0.0055653565,0.019458435,0.013865997,-0.0017569464,0.0060189804,0.008199084,0.016154429,-0.009600578,0.008375117,-0.0076235905,0.01684502,-0.019295944,0.018388696,-0.015098229,0.020000076,-0.011286435,0.022911394,0.013412373,-0.032417186,-0.008713642,-0.03087351,-0.007935033,-0.00016344426,-0.030494362,-0.01990529,0.0010604305,0.02954649,0.024576938,0.025443563,-0.002493239,-0.017874137,-0.01350716,-0.012349403,-0.018266827,-0.041245926,0.009681825,0.0014361937,-0.011266123,-0.02151667,-0.0063033416,-0.017616859,-0.002411993,-0.0025643294,0.009045397,0.022098932,-0.01738666,0.002325669,0.012897815,-0.01457013,-0.0047495104,0.0411376,-0.00045066184,0.01109686,-0.006564006,0.0018534261,-0.0068382113,0.0124238795,-0.0086053135,-0.0014302694,-0.0016325384,-0.021286473,0.0063947435,0.0011492935,-0.00048282175,0.011421844,0.0037237785,-0.03929602,-0.00077649247,0.005924193,0.029708983,-0.022708278,0.008300641,0.02754242,0.0013659496,-0.012051501,-0.02377802,-0.015937772,0.0048713796,-0.03504414,0.0040115253,-0.028300717,0.011320286,-0.012383256,0.013615489,-0.011936403,0.003163519,0.005707537,-0.018889714,0.014421179,0.02660809,-0.0027454405,0.011103631,0.0015529849,-0.0065132272,-0.009857858,-0.0010011886,0.015829444,-0.021313554,-0.0026540386,-0.025077956,-0.0028182233,0.005866644,0.0042180256,0.011550484,-0.00273867,-0.028029896,-0.004021681,0.022423917,0.010135449,-0.023425952,0.00935684,0.031036003,0.011652041,-0.010419809,-0.0060460623,-0.17484155,0.009444857,-0.004901847,-0.010033891,0.0129519785,0.021611456,0.008747495,0.0108666625,-0.010352104,0.0014463494,0.008314182,-0.042004224,-0.0382669,-0.006069759,0.009471939,-0.0025592514,-0.014651376,-0.0035274338,0.040975105,0.011516632,0.014461802,-0.0037610163,0.001115441,0.018266827,0.021557292,0.016154429,-0.009336528,-0.0075220326,0.01390662,0.0005357163,-0.0004043262,-0.0014404253,0.015748197,0.0036662293,0.009289135,0.005480725,-0.016736692,-0.005626291,-0.017738728,-0.007867329,0.0014319621,0.038375232,0.026134156,0.008706871,0.0051929783,0.025836254,0.030169377,-0.02819239,0.019837584,-0.0019600617,0.026811205,-0.031360988,0.00077691564,-0.012843651,0.012897815,0.0046005594,0.0049390844,0.019972995,-0.02472589,-0.014773245,-0.0027217437,-0.025782088,0.009600578,0.0041029267,-0.003155056,-0.033094235,-0.020203192,0.021543752,-0.028002815,-0.011442156,-0.015084689,-0.02434674,0.0004832449,-0.005886955,0.003327704,-0.0047427397,-0.027285142,0.013683193,0.0073053767,-0.014962819,0.0035579011,0.00095887296,0.0142316045,0.007941804,-0.033771288,-0.006723113,-0.015531542,0.024170708,0.007819935,-0.021340637,0.04869348,-0.04387288,-0.008023051,0.0069397693,0.03726487,0.0035748275,-0.0017671022,0.0055416594,-0.003001027,-0.008056902,-0.0028926989,0.007447557,-0.019404272,0.0054434873,0.0062254807,0.019404272,0.0039201234,0.008226166,0.041733403,0.004810445,-0.020907324,0.025145661,0.002687891,0.004383903,-0.003028109,0.023940511,0.00935684,0.0039370493,0.004502387,-0.0041096974,0.0601221,-0.010670318,-0.015572165,0.017833514,0.007847017,-0.012803027,-0.08530838,-0.021340637,0.022410376,0.014109735,-0.0074137044,0.027339306,0.004708887,0.021543752,-0.013324357,0.026770582,0.00020142256,-0.008456362,-0.0038930413,-0.02165208,-0.016344003,0.01565341,-0.025118578,-0.003554516,-0.015044065,0.015518001,-0.019228239,-0.01431285,-8.7487635e-05,-0.0060359067,-0.041218843,0.028544456,-0.022640573,-0.006205169,0.014448261,-0.012241076,0.0025643294,-0.016262757,0.010345334,-0.0058361767,0.00089201424,0.010406269,-0.022938477,-0.037671097,0.044089537,-0.0152878035,0.005504422,0.004617485,0.017968925,-0.017224168,0.0045802477,0.0096344305,-0.013195717,0.02421133,-0.01015576,-0.005893726,-0.051699586,0.004844297,-0.024441529,-0.02927567,-0.014218064,-0.021286473,0.010453662,-0.012085354,-0.020812538,-0.006320268,-0.0034529583,0.015220098,0.0055721267,0.009194348,0.014326392,0.011245811,-0.020744832,-0.021733325,0.014001408,-0.037616935,-0.009837546,0.020162567,-0.03328381,-0.0023070502,-0.034719158,0.0037339344,-0.0098849395,0.0076506725,0.013087389,0.00034973898,-0.014258686,0.00054291,-0.007941804,-0.019282402,0.0004578555,0.01777935,-0.023277001,-0.016073182,0.0011941481,-0.03341922,-0.0007540652,0.017034594,0.010237006,-0.0028571538,0.0065572355,-0.0129519785,0.026567467,-0.018131416,-0.010886975,0.018239744,-0.0073798522,-0.01859181,-0.067271754,0.00030721174,-0.012139518,-0.00013054383,0.0030771953,0.0044956165,0.025145661,-0.016235674,-0.0046716495,0.00045066184,-0.026919534,-0.010629695,-0.008199084,-0.014434719,-0.028923605,-0.007271524,0.014502425,0.0032329168,0.014014948,0.007427246,-0.0053148475,0.0018500409,0.008408969,0.017657481,-0.005653373,-0.0010062666,0.0029925639,-0.016993972,-0.009099561,-0.011665583,0.023290543,-0.00054883416,-0.009593808,0.021570833,-0.012545749,-0.009241741,0.0013684887,0.015193016,0.012904585,0.039187692,0.011347369,-0.021083357,0.009675054,-0.027975732,-0.014272228,-0.018998042,-0.03542329,0.011800993,0.005589053,-0.009566725,0.0011162873,0.013229569,0.005094806,-0.013358209,-0.0069126873,-0.044820752,-0.014434719,0.020419847,0.011591107,-0.017061677,0.031631805,-0.0029383998,0.0053588557,-0.015680494,0.026702877,-0.008564691,0.016019018,0.017671023,0.015721116,-0.0016680835,-0.021272931,-0.011814534,0.008056902,0.018740762,0.025592515,-0.01936365,-0.0068179,0.011313517,-0.038456477,0.0339067,0.0021140906,0.019471977,-0.015220098,0.017142922,0.023439493,-0.012620224,-0.0066114,-0.0151117705,0.0054874956,0.009715677,-0.011692665,0.012356174,-0.0025863335,0.010392727,-0.024021758,0.007603279,0.008740724,-0.005629676,0.010704171,0.013852457,-0.014800327,0.0011983797,-0.0037914836,-0.01791476,-0.044414524,0.01163173,-0.025430022,-0.015382591,-0.004702117,0.013466537,0.035233717,0.0030991994,0.043114584,0.0011255967,-0.01565341,-0.0006461602,-0.023073886,-0.01176037,-0.021895818,0.0030247238,-0.022126015,-0.002144558,0.024766512,-0.03244427,0.039756414,0.01270147,0.020501094,-0.026499763,-0.00026299187,-0.010636466,0.003916738,-0.022423917,0.0031652118,-0.0030805804,-0.011211959,-0.0068652937,-0.014962819,-0.0033243187,0.0053487,0.07447557,0.009099561,-0.021232309,-0.030331869,0.007156425,-0.009377152,-0.006056218,0.0076709837,0.021679161,-0.03008813,0.042762518,-0.029031932,0.010196383,-0.024279036,-0.011103631,-0.005616135,0.007928263,0.010832811,0.008984462,0.008808429,0.008131378,0.020704208,0.018822009,0.009431316,-0.03580244,-0.014096195,0.029438162,0.001199226,0.002620186,-0.039241854,-0.0026049523,0.008984462,-0.03501706,0.005958046,0.007461098,-0.023710314,-0.025023792,-0.003798254,0.021476047,0.044902,0.016520036,0.032796334,-0.03257968,-0.018537646,-0.030331869,-0.012742093,-0.0022545788,-0.004065689,0.003727164] | K3: 2025-07-27T18:28:57.031Z
